2025-05-28 14:35:11,858 - clashbot - INFO - Successfully initialized bot resources
2025-05-28 14:35:12,184 - clashbot - INFO - Loaded src.cogs.utility_commands
2025-05-28 14:35:12,188 - clashbot - INFO - Loaded src.cogs.summoner_commands
2025-05-28 14:35:12,189 - clashbot - INFO - Loaded src.cogs.match_commands
2025-05-28 14:35:12,192 - clashbot - ERROR - Failed to load src.cogs.team_commands: Extension 'src.cogs.team_commands' raised an error: NameError: name 'Account' is not defined
2025-05-28 14:35:14,092 - clashbot - INFO - Summoner command invoked by ry3ry3bread for rye#rye in na1
2025-05-28 14:35:14,092 - clashbot - DEBUG - Fetching account info for rye#rye
2025-05-28 14:35:14,092 - clashbot - DEBUG - Getting account by Riot ID: rye#rye
2025-05-28 14:35:14,573 - clashbot - DEBUG - Fetching summoner info for Rye#Rye
2025-05-28 14:35:14,573 - clashbot - DEBUG - Getting summoner by PUUID: Yt5_ZRikaBlMbxx5Iy_21eAM-c3xi41pjF1FmrKQy2Ki4EkEBOhsd6e1ZhYI8fqTIVO8d5J3Uv9UIA
2025-05-28 14:35:15,010 - clashbot - ERROR - An error occurred while processing the summoner command: 'Summoner' object has no attribute 'name'
Traceback (most recent call last):
  File "C:\Users\riley\Desktop\ClashBot\ClashBot\src\cogs\summoner_commands.py", line 54, in cmd_summoner
    self.logger.debug(f"Fetching league entries for {summoner.name}")
                                                     ^^^^^^^^^^^^^
AttributeError: 'Summoner' object has no attribute 'name'
